
The following have been reloaded with a version change:
  1) gcc/4.8.5 => gcc/11.4.0


Currently Loaded Modules:
  1) StdEnv   2) gcc/11.4.0   3) openblas/0.3.20   4) python/3.11.6

 

Traceback (most recent call last):
  File "/cluster/home/bzemann/hpc_lab/project2/mandel/strong_scaling.py", line 78, in <module>
    plot_strong(n_threads, serial_time_avg, par_crit_tim_avg, par_red_tim_avg)
  File "/cluster/home/bzemann/hpc_lab/project2/mandel/strong_scaling.py", line 11, in plot_strong
    plt.plot(n_threads, speedup_red, label='reduction')
  File "/cluster/apps/nss/gcc-11.4.0/python/3.11.6/x86_64/lib64/python3.11/site-packages/matplotlib/pyplot.py", line 3575, in plot
    return gca().plot(
           ^^^^^^^^^^^
  File "/cluster/apps/nss/gcc-11.4.0/python/3.11.6/x86_64/lib64/python3.11/site-packages/matplotlib/axes/_axes.py", line 1721, in plot
    lines = [*self._get_lines(self, *args, data=data, **kwargs)]
            ^^^^^^^^^^^^^^^^^^^^^^^^^^^^^^^^^^^^^^^^^^^^^^^^^^^^
  File "/cluster/apps/nss/gcc-11.4.0/python/3.11.6/x86_64/lib64/python3.11/site-packages/matplotlib/axes/_base.py", line 303, in __call__
    yield from self._plot_args(
               ^^^^^^^^^^^^^^^^
  File "/cluster/apps/nss/gcc-11.4.0/python/3.11.6/x86_64/lib64/python3.11/site-packages/matplotlib/axes/_base.py", line 499, in _plot_args
    raise ValueError(f"x and y must have same first dimension, but "
ValueError: x and y must have same first dimension, but have shapes (8,) and (7,)
